[2022-12-12 12:43:57,252] {taskinstance.py:1159} INFO - Dependencies all met for <TaskInstance: daily_Paper.get_news_task manual__2022-12-12T12:43:56.398057+00:00 [queued]>
[2022-12-12 12:43:57,261] {taskinstance.py:1159} INFO - Dependencies all met for <TaskInstance: daily_Paper.get_news_task manual__2022-12-12T12:43:56.398057+00:00 [queued]>
[2022-12-12 12:43:57,261] {taskinstance.py:1356} INFO - 
--------------------------------------------------------------------------------
[2022-12-12 12:43:57,262] {taskinstance.py:1357} INFO - Starting attempt 1 of 2
[2022-12-12 12:43:57,262] {taskinstance.py:1358} INFO - 
--------------------------------------------------------------------------------
[2022-12-12 12:43:57,275] {taskinstance.py:1377} INFO - Executing <Task(PythonOperator): get_news_task> on 2022-12-12 12:43:56.398057+00:00
[2022-12-12 12:43:57,280] {standard_task_runner.py:52} INFO - Started process 748 to run task
[2022-12-12 12:43:57,285] {standard_task_runner.py:79} INFO - Running: ['***', 'tasks', 'run', 'daily_Paper', 'get_news_task', 'manual__2022-12-12T12:43:56.398057+00:00', '--job-id', '26', '--raw', '--subdir', 'DAGS_FOLDER/morning-paper.py', '--cfg-path', '/tmp/tmpnv2u1xmf', '--error-file', '/tmp/tmpd7o_zdnj']
[2022-12-12 12:43:57,287] {standard_task_runner.py:80} INFO - Job 26: Subtask get_news_task
[2022-12-12 12:43:57,350] {task_command.py:369} INFO - Running <TaskInstance: daily_Paper.get_news_task manual__2022-12-12T12:43:56.398057+00:00 [running]> on host cbcd6542cb8e
[2022-12-12 12:43:57,418] {taskinstance.py:1571} INFO - Exporting the following env vars:
AIRFLOW_CTX_DAG_EMAIL=akash.khamkar40@gmail.com
AIRFLOW_CTX_DAG_OWNER=akashk
AIRFLOW_CTX_DAG_ID=daily_Paper
AIRFLOW_CTX_TASK_ID=get_news_task
AIRFLOW_CTX_EXECUTION_DATE=2022-12-12T12:43:56.398057+00:00
AIRFLOW_CTX_TRY_NUMBER=1
AIRFLOW_CTX_DAG_RUN_ID=manual__2022-12-12T12:43:56.398057+00:00
[2022-12-12 12:43:58,130] {taskinstance.py:1889} ERROR - Task failed with exception
Traceback (most recent call last):
  File "/home/airflow/.local/lib/python3.7/site-packages/airflow/operators/python.py", line 171, in execute
    return_value = self.execute_callable()
  File "/home/airflow/.local/lib/python3.7/site-packages/airflow/operators/python.py", line 189, in execute_callable
    return self.python_callable(*self.op_args, **self.op_kwargs)
  File "/opt/airflow/dags/morning_paper_src/news.py", line 10, in get_news
    news = json.loads(res.text)
NameError: name 'json' is not defined
[2022-12-12 12:43:58,164] {taskinstance.py:1400} INFO - Marking task as UP_FOR_RETRY. dag_id=daily_Paper, task_id=get_news_task, execution_date=20221212T124356, start_date=20221212T124357, end_date=20221212T124358
[2022-12-12 12:43:58,177] {standard_task_runner.py:97} ERROR - Failed to execute job 26 for task get_news_task (name 'json' is not defined; 748)
[2022-12-12 12:43:58,207] {local_task_job.py:156} INFO - Task exited with return code 1
[2022-12-12 12:43:58,241] {local_task_job.py:273} INFO - 0 downstream tasks scheduled from follow-on schedule check
