[2022-12-13 09:52:20,138] {taskinstance.py:1159} INFO - Dependencies all met for <TaskInstance: cereal_paper.save_to_db_task manual__2022-12-13T09:52:15.702096+00:00 [queued]>
[2022-12-13 09:52:20,145] {taskinstance.py:1159} INFO - Dependencies all met for <TaskInstance: cereal_paper.save_to_db_task manual__2022-12-13T09:52:15.702096+00:00 [queued]>
[2022-12-13 09:52:20,146] {taskinstance.py:1356} INFO - 
--------------------------------------------------------------------------------
[2022-12-13 09:52:20,146] {taskinstance.py:1357} INFO - Starting attempt 1 of 2
[2022-12-13 09:52:20,147] {taskinstance.py:1358} INFO - 
--------------------------------------------------------------------------------
[2022-12-13 09:52:20,157] {taskinstance.py:1377} INFO - Executing <Task(PythonOperator): save_to_db_task> on 2022-12-13 09:52:15.702096+00:00
[2022-12-13 09:52:20,160] {standard_task_runner.py:52} INFO - Started process 358 to run task
[2022-12-13 09:52:20,164] {standard_task_runner.py:79} INFO - Running: ['***', 'tasks', 'run', 'cereal_paper', 'save_to_db_task', 'manual__2022-12-13T09:52:15.702096+00:00', '--job-id', '84', '--raw', '--subdir', 'DAGS_FOLDER/cereal-paper.py', '--cfg-path', '/tmp/tmpoii2jgbl', '--error-file', '/tmp/tmpkcu9jiww']
[2022-12-13 09:52:20,168] {standard_task_runner.py:80} INFO - Job 84: Subtask save_to_db_task
[2022-12-13 09:52:20,233] {task_command.py:369} INFO - Running <TaskInstance: cereal_paper.save_to_db_task manual__2022-12-13T09:52:15.702096+00:00 [running]> on host 2c020bbaa31c
[2022-12-13 09:52:20,312] {taskinstance.py:1571} INFO - Exporting the following env vars:
AIRFLOW_CTX_DAG_EMAIL=akash.khamkar40@gmail.com
AIRFLOW_CTX_DAG_OWNER=akashk
AIRFLOW_CTX_DAG_ID=cereal_paper
AIRFLOW_CTX_TASK_ID=save_to_db_task
AIRFLOW_CTX_EXECUTION_DATE=2022-12-13T09:52:15.702096+00:00
AIRFLOW_CTX_TRY_NUMBER=1
AIRFLOW_CTX_DAG_RUN_ID=manual__2022-12-13T09:52:15.702096+00:00
[2022-12-13 09:52:20,330] {taskinstance.py:1889} ERROR - Task failed with exception
Traceback (most recent call last):
  File "/home/airflow/.local/lib/python3.7/site-packages/airflow/operators/python.py", line 171, in execute
    return_value = self.execute_callable()
  File "/home/airflow/.local/lib/python3.7/site-packages/airflow/operators/python.py", line 189, in execute_callable
    return self.python_callable(*self.op_args, **self.op_kwargs)
  File "/opt/airflow/dags/cereal_paper_src/mongo_utils.py", line 11, in save_to_db
    cereal_db = get_database()
  File "/opt/airflow/dags/cereal_paper_src/mongo_utils.py", line 5, in get_database
    client = MongoClient(CONNECTION_STRING)
  File "/home/airflow/.local/lib/python3.7/site-packages/pymongo/mongo_client.py", line 744, in __init__
    srv_max_hosts=srv_max_hosts,
  File "/home/airflow/.local/lib/python3.7/site-packages/pymongo/uri_parser.py", line 541, in parse_uri
    dns_resolver = _SrvResolver(fqdn, connect_timeout, srv_service_name, srv_max_hosts)
  File "/home/airflow/.local/lib/python3.7/site-packages/pymongo/srv_resolver.py", line 73, in __init__
    raise ConfigurationError(_INVALID_HOST_MSG % (fqdn,))
pymongo.errors.ConfigurationError: Invalid URI host: mongodb is not a valid hostname for 'mongodb+srv://'. Did you mean to use 'mongodb://'?
[2022-12-13 09:52:20,345] {taskinstance.py:1400} INFO - Marking task as UP_FOR_RETRY. dag_id=cereal_paper, task_id=save_to_db_task, execution_date=20221213T095215, start_date=20221213T095220, end_date=20221213T095220
[2022-12-13 09:52:20,358] {standard_task_runner.py:97} ERROR - Failed to execute job 84 for task save_to_db_task (Invalid URI host: mongodb is not a valid hostname for 'mongodb+srv://'. Did you mean to use 'mongodb://'?; 358)
[2022-12-13 09:52:20,381] {local_task_job.py:156} INFO - Task exited with return code 1
[2022-12-13 09:52:20,421] {local_task_job.py:273} INFO - 0 downstream tasks scheduled from follow-on schedule check
