[2022-12-12 16:54:28,825] {taskinstance.py:1159} INFO - Dependencies all met for <TaskInstance: daily_paper.create_pdf_task manual__2022-12-12T16:54:25.464030+00:00 [queued]>
[2022-12-12 16:54:28,830] {taskinstance.py:1159} INFO - Dependencies all met for <TaskInstance: daily_paper.create_pdf_task manual__2022-12-12T16:54:25.464030+00:00 [queued]>
[2022-12-12 16:54:28,831] {taskinstance.py:1356} INFO - 
--------------------------------------------------------------------------------
[2022-12-12 16:54:28,831] {taskinstance.py:1357} INFO - Starting attempt 1 of 2
[2022-12-12 16:54:28,832] {taskinstance.py:1358} INFO - 
--------------------------------------------------------------------------------
[2022-12-12 16:54:28,840] {taskinstance.py:1377} INFO - Executing <Task(PythonOperator): create_pdf_task> on 2022-12-12 16:54:25.464030+00:00
[2022-12-12 16:54:28,843] {standard_task_runner.py:52} INFO - Started process 404 to run task
[2022-12-12 16:54:28,847] {standard_task_runner.py:79} INFO - Running: ['***', 'tasks', 'run', 'daily_paper', 'create_pdf_task', 'manual__2022-12-12T16:54:25.464030+00:00', '--job-id', '187', '--raw', '--subdir', 'DAGS_FOLDER/morning-paper.py', '--cfg-path', '/tmp/tmp8ejvjd25', '--error-file', '/tmp/tmp8s13cwn0']
[2022-12-12 16:54:28,848] {standard_task_runner.py:80} INFO - Job 187: Subtask create_pdf_task
[2022-12-12 16:54:28,886] {task_command.py:369} INFO - Running <TaskInstance: daily_paper.create_pdf_task manual__2022-12-12T16:54:25.464030+00:00 [running]> on host 6bb81baa0a52
[2022-12-12 16:54:28,932] {taskinstance.py:1571} INFO - Exporting the following env vars:
AIRFLOW_CTX_DAG_EMAIL=akash.khamkar40@gmail.com
AIRFLOW_CTX_DAG_OWNER=akashk
AIRFLOW_CTX_DAG_ID=daily_paper
AIRFLOW_CTX_TASK_ID=create_pdf_task
AIRFLOW_CTX_EXECUTION_DATE=2022-12-12T16:54:25.464030+00:00
AIRFLOW_CTX_TRY_NUMBER=1
AIRFLOW_CTX_DAG_RUN_ID=manual__2022-12-12T16:54:25.464030+00:00
[2022-12-12 16:54:28,941] {taskinstance.py:1889} ERROR - Task failed with exception
Traceback (most recent call last):
  File "/home/airflow/.local/lib/python3.7/site-packages/airflow/operators/python.py", line 171, in execute
    return_value = self.execute_callable()
  File "/home/airflow/.local/lib/python3.7/site-packages/airflow/operators/python.py", line 189, in execute_callable
    return self.python_callable(*self.op_args, **self.op_kwargs)
  File "/opt/airflow/dags/morning_paper_src/pdf.py", line 34, in create_pdf
    regular(pdf, article['joke'])
  File "/opt/airflow/dags/morning_paper_src/pdf.py", line 19, in regular
    pdf.multi_cell(0, 10, txt = text, ln = 1, align = 'L')
  File "/home/airflow/.local/lib/python3.7/site-packages/fpdf/fpdf.py", line 150, in wrapper
    return fn(self, *args, **kwargs)
TypeError: multi_cell() got an unexpected keyword argument 'ln'
[2022-12-12 16:54:28,950] {taskinstance.py:1400} INFO - Marking task as UP_FOR_RETRY. dag_id=daily_paper, task_id=create_pdf_task, execution_date=20221212T165425, start_date=20221212T165428, end_date=20221212T165428
[2022-12-12 16:54:28,957] {standard_task_runner.py:97} ERROR - Failed to execute job 187 for task create_pdf_task (multi_cell() got an unexpected keyword argument 'ln'; 404)
[2022-12-12 16:54:28,978] {local_task_job.py:156} INFO - Task exited with return code 1
[2022-12-12 16:54:29,000] {local_task_job.py:273} INFO - 0 downstream tasks scheduled from follow-on schedule check
