[2022-12-12 16:22:09,204] {taskinstance.py:1159} INFO - Dependencies all met for <TaskInstance: daily_paper.create_pdf_task manual__2022-12-12T16:22:04.806682+00:00 [queued]>
[2022-12-12 16:22:09,209] {taskinstance.py:1159} INFO - Dependencies all met for <TaskInstance: daily_paper.create_pdf_task manual__2022-12-12T16:22:04.806682+00:00 [queued]>
[2022-12-12 16:22:09,210] {taskinstance.py:1356} INFO - 
--------------------------------------------------------------------------------
[2022-12-12 16:22:09,210] {taskinstance.py:1357} INFO - Starting attempt 1 of 2
[2022-12-12 16:22:09,210] {taskinstance.py:1358} INFO - 
--------------------------------------------------------------------------------
[2022-12-12 16:22:09,217] {taskinstance.py:1377} INFO - Executing <Task(PythonOperator): create_pdf_task> on 2022-12-12 16:22:04.806682+00:00
[2022-12-12 16:22:09,220] {standard_task_runner.py:52} INFO - Started process 2857 to run task
[2022-12-12 16:22:09,223] {standard_task_runner.py:79} INFO - Running: ['***', 'tasks', 'run', 'daily_paper', 'create_pdf_task', 'manual__2022-12-12T16:22:04.806682+00:00', '--job-id', '120', '--raw', '--subdir', 'DAGS_FOLDER/morning-paper.py', '--cfg-path', '/tmp/tmpif0zeip9', '--error-file', '/tmp/tmptphnnmi1']
[2022-12-12 16:22:09,224] {standard_task_runner.py:80} INFO - Job 120: Subtask create_pdf_task
[2022-12-12 16:22:09,263] {task_command.py:369} INFO - Running <TaskInstance: daily_paper.create_pdf_task manual__2022-12-12T16:22:04.806682+00:00 [running]> on host cbcd6542cb8e
[2022-12-12 16:22:09,307] {taskinstance.py:1571} INFO - Exporting the following env vars:
AIRFLOW_CTX_DAG_EMAIL=akash.khamkar40@gmail.com
AIRFLOW_CTX_DAG_OWNER=akashk
AIRFLOW_CTX_DAG_ID=daily_paper
AIRFLOW_CTX_TASK_ID=create_pdf_task
AIRFLOW_CTX_EXECUTION_DATE=2022-12-12T16:22:04.806682+00:00
AIRFLOW_CTX_TRY_NUMBER=1
AIRFLOW_CTX_DAG_RUN_ID=manual__2022-12-12T16:22:04.806682+00:00
[2022-12-12 16:22:09,308] {taskinstance.py:1889} ERROR - Task failed with exception
Traceback (most recent call last):
  File "/home/airflow/.local/lib/python3.7/site-packages/airflow/operators/python.py", line 171, in execute
    return_value = self.execute_callable()
  File "/home/airflow/.local/lib/python3.7/site-packages/airflow/operators/python.py", line 189, in execute_callable
    return self.python_callable(*self.op_args, **self.op_kwargs)
  File "/opt/airflow/dags/morning_paper_src/pdf.py", line 28, in create_pdf
    pdf = PDF()
  File "/opt/airflow/dags/morning_paper_src/pdf.py", line 8, in __init__
    self.set_font('Monospace', 'C', 12)
  File "/home/airflow/.local/lib/python3.7/site-packages/fpdf/fpdf.py", line 585, in set_font
    if(self.font_family==family and self.font_style==style and self.font_size_pt==size):
AttributeError: 'PDF' object has no attribute 'font_family'
[2022-12-12 16:22:09,317] {taskinstance.py:1400} INFO - Marking task as UP_FOR_RETRY. dag_id=daily_paper, task_id=create_pdf_task, execution_date=20221212T162204, start_date=20221212T162209, end_date=20221212T162209
[2022-12-12 16:22:09,322] {standard_task_runner.py:97} ERROR - Failed to execute job 120 for task create_pdf_task ('PDF' object has no attribute 'font_family'; 2857)
[2022-12-12 16:22:09,360] {local_task_job.py:156} INFO - Task exited with return code 1
[2022-12-12 16:22:09,382] {local_task_job.py:273} INFO - 0 downstream tasks scheduled from follow-on schedule check
