[2022-12-12 16:49:06,115] {taskinstance.py:1159} INFO - Dependencies all met for <TaskInstance: daily_paper.create_pdf_task manual__2022-12-12T16:49:02.284719+00:00 [queued]>
[2022-12-12 16:49:06,120] {taskinstance.py:1159} INFO - Dependencies all met for <TaskInstance: daily_paper.create_pdf_task manual__2022-12-12T16:49:02.284719+00:00 [queued]>
[2022-12-12 16:49:06,120] {taskinstance.py:1356} INFO - 
--------------------------------------------------------------------------------
[2022-12-12 16:49:06,121] {taskinstance.py:1357} INFO - Starting attempt 1 of 2
[2022-12-12 16:49:06,121] {taskinstance.py:1358} INFO - 
--------------------------------------------------------------------------------
[2022-12-12 16:49:06,128] {taskinstance.py:1377} INFO - Executing <Task(PythonOperator): create_pdf_task> on 2022-12-12 16:49:02.284719+00:00
[2022-12-12 16:49:06,131] {standard_task_runner.py:52} INFO - Started process 328 to run task
[2022-12-12 16:49:06,134] {standard_task_runner.py:79} INFO - Running: ['***', 'tasks', 'run', 'daily_paper', 'create_pdf_task', 'manual__2022-12-12T16:49:02.284719+00:00', '--job-id', '174', '--raw', '--subdir', 'DAGS_FOLDER/morning-paper.py', '--cfg-path', '/tmp/tmppga9pazb', '--error-file', '/tmp/tmpcv4no2sy']
[2022-12-12 16:49:06,135] {standard_task_runner.py:80} INFO - Job 174: Subtask create_pdf_task
[2022-12-12 16:49:06,172] {task_command.py:369} INFO - Running <TaskInstance: daily_paper.create_pdf_task manual__2022-12-12T16:49:02.284719+00:00 [running]> on host 6bb81baa0a52
[2022-12-12 16:49:06,217] {taskinstance.py:1571} INFO - Exporting the following env vars:
AIRFLOW_CTX_DAG_EMAIL=akash.khamkar40@gmail.com
AIRFLOW_CTX_DAG_OWNER=akashk
AIRFLOW_CTX_DAG_ID=daily_paper
AIRFLOW_CTX_TASK_ID=create_pdf_task
AIRFLOW_CTX_EXECUTION_DATE=2022-12-12T16:49:02.284719+00:00
AIRFLOW_CTX_TRY_NUMBER=1
AIRFLOW_CTX_DAG_RUN_ID=manual__2022-12-12T16:49:02.284719+00:00
[2022-12-12 16:49:06,226] {taskinstance.py:1889} ERROR - Task failed with exception
Traceback (most recent call last):
  File "/home/airflow/.local/lib/python3.7/site-packages/airflow/operators/python.py", line 171, in execute
    return_value = self.execute_callable()
  File "/home/airflow/.local/lib/python3.7/site-packages/airflow/operators/python.py", line 189, in execute_callable
    return self.python_callable(*self.op_args, **self.op_kwargs)
  File "/opt/airflow/dags/morning_paper_src/pdf.py", line 48, in create_pdf
    pdf.output('./temp/cereal_paper.pdf', 'F')
  File "/home/airflow/.local/lib/python3.7/site-packages/fpdf/fpdf.py", line 1065, in output
    self.close()
  File "/home/airflow/.local/lib/python3.7/site-packages/fpdf/fpdf.py", line 246, in close
    self._enddoc()
  File "/home/airflow/.local/lib/python3.7/site-packages/fpdf/fpdf.py", line 1636, in _enddoc
    self._putpages()
  File "/home/airflow/.local/lib/python3.7/site-packages/fpdf/fpdf.py", line 1170, in _putpages
    p = self.pages[n].encode("latin1") if PY3K else self.pages[n]
UnicodeEncodeError: 'latin-1' codec can't encode character '\u2013' in position 647: ordinal not in range(256)
[2022-12-12 16:49:06,234] {taskinstance.py:1400} INFO - Marking task as UP_FOR_RETRY. dag_id=daily_paper, task_id=create_pdf_task, execution_date=20221212T164902, start_date=20221212T164906, end_date=20221212T164906
[2022-12-12 16:49:06,240] {standard_task_runner.py:97} ERROR - Failed to execute job 174 for task create_pdf_task ('latin-1' codec can't encode character '\u2013' in position 647: ordinal not in range(256); 328)
[2022-12-12 16:49:06,267] {local_task_job.py:156} INFO - Task exited with return code 1
[2022-12-12 16:49:06,288] {local_task_job.py:273} INFO - 0 downstream tasks scheduled from follow-on schedule check
